# 异常

`Dart` 中的每个异常都是预定义类 `Exception` 的子类型。必须处理异常以防止应用程序突然终止。

分为以下异常：

- DeferredLoadException：延迟库无法加载时抛出。
- FormatException：当字符串或某些其他数据不具有预期格式且无法解析或处理时抛出异常。。
- IntegerDivisionByZeroException：当数字除以零时抛出。
- IOException：所有与Inupt-Output相关的异常的基类。
- IsolateSpawnException：无法创建隔离时抛出。
- Timeout：在等待异步结果时发生计划超时时抛出。

## try、on、catch、finally 块

`try` 嵌入可能会导致异常代码块。`on` 用来捕获特定异常的代码块。`catch` 用来捕获任何异常的代码块。

- 代码段可以有多个 `on` / `catch` 块来处理多个异常。
- 如果一个异常被 `on` 所在的代码块捕获住，`catch` 将不再处理，直接跳到 `finally` 代码块。
- `catch` 既然不能针对性捕获，却可以获得异常对象 e。
- 也可同时使用:
  ``` dart
  main() {
    int x = 12, y = 0, res;  

    try {
      res = x ~/ y;
    } on IntegerDivisionByZeroException catch(e) {
      print(e);
    }
  }
  ```
- 如果捕获异常并处理后还允许该异常继续传播，可以使用 `rethrow` 关键字。
  ``` dart
  void misbehave() {
    int x = 12, y = 0, res;
    try {
      res = x ~/ y;
    } on IntegerDivisionByZeroException catch(e) {
      print(e);
      rethrow;
    }
  }

  void main() {
    try {
      misbehave();
    } catch (e) {
      print('main() finished handling ${e.runtimeType}.');
    }
  }
  ```

## 抛出异常

`throw` 关键字用来明确地抛出异常。也可自定义异常：

    throw new Exception_name()

``` dart
class AmtException implements Exception {
  String errMsg() {
    return 'Amount should be greater than zero';
  }
}  

void withdraw_amt(int amt) {
  if (amt <= 0) {
    throw new AmtException();
  }
}

void main() {
  try {
    withdraw_amt(-1);
  }
  catch(e) {
    print(e.errMsg());
  }  
  finally {
    print('Ending requested operation.....');
  }
}
```
